<?xml version="1.0"?>
<robot name="bartender_robot">

    <!-- Base fixa (invertida) -->
    <link name="base">
        <visual>
            <geometry>
                <box size="0.95 0.35 0.15"/>
            </geometry>
            <material name="white">
                <color rgba="1 1 1 1"/>
            </material>
        </visual>
        <collision>
            <geometry>
                <box size="0.35 0.35 0.15"/>
            </geometry>
        </collision>
        <inertial>
            <mass value="10.0"/>
            <origin xyz="0.2 0 0"/>
            <inertia ixx="0.5" ixy="0.0" ixz="0.0" iyy="0.5" iyz="0.0" izz="0.5"/>
        </inertial>
    </link>

    <!-- Bancada adicional -->
    <link name="countertop">
        <visual>
            <geometry>
                <box size="1.2 0.5 0.1"/>
            </geometry>
            <material name="wood">
                <color rgba="0.6 0.3 0.1 1"/>
            </material>
        </visual>
        <collision>
            <geometry>
                <box size="1.2 0.5 0.1"/>
            </geometry>
        </collision>
        <inertial>
            <mass value="15.0"/>
            <origin xyz="0 0 -0.1"/>
            <inertia ixx="1.0" ixy="0.0" ixz="0.0" iyy="1.0" iyz="0.0" izz="1.0"/>
        </inertial>
    </link>
    <joint name="joint_countertop" type="fixed">
        <parent link="base"/>
        <child link="countertop"/>
        <origin xyz="0 0 -1.05" rpy="0 0 0"/>
    </joint>

    <!-- Tablet no Countertop -->
    <link name="tablet">
        <visual>
            <geometry>
                <box size="0.3 0.02 0.2"/>
            </geometry>
            <material name="dark_gray">
                <color rgba="0.2 0.2 0.2 1"/>
            </material>
        </visual>
        <collision>
            <geometry>
                <box size="0.3 0.02 0.2"/>
            </geometry>
        </collision>
    </link>
    <joint name="joint_tablet" type="fixed">
        <parent link="countertop"/>
        <child link="tablet"/>
        <!-- Posição do tablet sobre a bancada -->
        <origin xyz="0.0 0.25 0.1" rpy="0 0 0"/>
    </joint>


    <!-- Alto-falantes -->
    <link name="speaker_front_left">
        <visual>
            <geometry>
                <cylinder radius="0.025" length="0.02"/>
            </geometry>
            <material name="black">
                <color rgba="0 0 0 1"/>
            </material>
        </visual>
    </link>
    <joint name="joint_speaker_front_left" type="fixed">
        <parent link="base"/>
        <child link="speaker_front_left"/>
        <origin xyz="0.125 0.125 -0.075" rpy="0 0 0"/>
    </joint>

    <link name="speaker_front_right">
        <visual>
            <geometry>
                <cylinder radius="0.025" length="0.02"/>
            </geometry>
            <material name="black"/>
        </visual>
    </link>
    <joint name="joint_speaker_front_right" type="fixed">
        <parent link="base"/>
        <child link="speaker_front_right"/>
        <origin xyz="-0.125 0.125 -0.075" rpy="0 0 0"/>
    </joint>

    <link name="speaker_back_left">
        <visual>
            <geometry>
                <cylinder radius="0.025" length="0.02"/>
            </geometry>
            <material name="black"/>
        </visual>
    </link>
    <joint name="joint_speaker_back_left" type="fixed">
        <parent link="base"/>
        <child link="speaker_back_left"/>
        <origin xyz="0.125 -0.125 -0.075" rpy="0 0 0"/>
    </joint>

    <link name="speaker_back_right">
        <visual>
            <geometry>
                <cylinder radius="0.025" length="0.02"/>
            </geometry>
            <material name="black"/>
        </visual>
    </link>
    <joint name="joint_speaker_back_right" type="fixed">
        <parent link="base"/>
        <child link="speaker_back_right"/>
        <origin xyz="-0.125 -0.125 -0.075" rpy="0 0 0"/>
    </joint>

    <!-- Braços -->
    <link name="arm_left">
        <visual>
            <geometry>
                <cylinder radius="0.05" length="0.5"/>
            </geometry>
            <material name="blue">
                <color rgba="0 0 1 1"/>
            </material>
        </visual>
	<inertial>
    		<mass value="2.0"/>
    		<origin xyz="0 0 -0.25"/>
    		<inertia ixx="0.1" ixy="0.0" ixz="0.0" iyy="0.1" iyz="0.0" izz="0.02"/>
		</inertial>
    </link>
    <joint name="joint_arm_left" type="revolute">
        <parent link="base"/>
        <child link="arm_left"/>
        <origin xyz="-0.35 0 -0.275" rpy="0 0 3.1416"/>
        <axis xyz="0 1 0"/>
		<limit lower="-0.3" upper="0.3" effort="10" velocity="1.0"/>
    </joint>

    <link name="arm_right">
        <visual>
            <geometry>
                <cylinder radius="0.05" length="0.5"/>
            </geometry>
            <material name="blue">
                <color rgba="0 0 1 1"/>
            </material>
        </visual>
	<inertial>
    		<mass value="2.0"/>
    		<origin xyz="0 0 -0.25"/>
    		<inertia ixx="0.1" ixy="0.0" ixz="0.0" iyy="0.1" iyz="0.0" izz="0.02"/>
		</inertial>
    </link>
    <joint name="joint_arm_right" type="revolute">
        <parent link="base"/>
        <child link="arm_right"/>
        <origin xyz="0.35 0 -0.275" rpy="0 0 3.1416"/>
        <axis xyz="0 1 0"/>
		<limit lower="0.3" upper="-0.3" effort="10" velocity="1.0"/>
    </joint>

<!-- Antebraços -->
    <link name="forearm_left">
        <visual>
            <geometry>
                <cylinder radius="0.04" length="0.4"/>
            </geometry>
            <material name="green">
                <color rgba="0 1 0 1"/>
            </material>
        </visual>
	<inertial>
    		<mass value="1.5"/>
    		<origin xyz="0 0 -0.2"/>
    		<inertia ixx="0.05" ixy="0.0" ixz="0.0" iyy="0.05" iyz="0.0" izz="0.01"/>
		</inertial>
    </link>
    <joint name="joint_forearm_left" type="revolute">
        <parent link="arm_left"/>
        <child link="forearm_left"/>
        <origin xyz="0 0 -0.25" rpy="0 0 0"/>
        <axis xyz="1 0 0"/>
		<limit lower="-0.185" upper="0.185" effort="10" velocity="1.0"/>
    </joint>

    <link name="forearm_right">
        <visual>
            <geometry>
                <cylinder radius="0.04" length="0.4"/>
            </geometry>
            <material name="green">
                <color rgba="0 1 0 1"/>
            </material>
        </visual>
	<inertial>
    	<mass value="1.5"/>
    	<origin xyz="0 0 -0.2"/>
    	<inertia ixx="0.05" ixy="0.0" ixz="0.0" iyy="0.05" iyz="0.0" izz="0.01"/>
	</inertial>

    </link>
    <joint name="joint_forearm_right" type="revolute">
        <parent link="arm_right"/>
        <child link="forearm_right"/>
        <origin xyz="0 0 -0.25" rpy="0 0 0"/>
        <axis xyz="1 0 0"/>
		<limit lower="-0.185" upper="0.185" effort="10" velocity="1.0"/>
    </joint>

    <!-- Bases das garras -->
    <link name="gripper_base_left">
        <visual>
            <geometry>
                <box size="0.135 0.12 0.05"/>
            </geometry>
            <material name="gray">
                <color rgba="0.5 0.5 0.5 1"/>
            </material>
        </visual>
		<inertial>
    		<mass value="0.5"/>
    		<origin xyz="0 0 -0.1"/>
    		<inertia ixx="0.02" ixy="0.0" ixz="0.0" iyy="0.02" iyz="0.0" izz="0.005"/>
		</inertial>
    </link>
    <joint name="joint_gripper_base_left_rotation" type="revolute">
    	<parent link="forearm_left"/>
    	<child link="gripper_base_left"/>
    	<origin xyz="0 0 -0.2" rpy="0 0 0"/>
    	<axis xyz="0 0 1"/>
    	<limit lower="-1.57" upper="0.0" effort="5" velocity="1.0"/>
</joint>

    <link name="gripper_base_right">
        <visual>
            <geometry>
                <box size="0.135 0.12 0.05"/>
            </geometry>
            <material name="gray">
                <color rgba="0.5 0.5 0.5 1"/>
            </material>
        </visual>
		<inertial>
    		<mass value="0.5"/>
    		<origin xyz="0 0 -0.1"/>
    		<inertia ixx="0.02" ixy="0.0" ixz="0.0" iyy="0.02" iyz="0.0" izz="0.005"/>
		</inertial>
    </link>
    <joint name="joint_gripper_base_right_rotation" type="revolute">
    	<parent link="forearm_right"/>
    	<child link="gripper_base_right"/>
    	<origin xyz="0 0 -0.2" rpy="0 0 0"/>
    	<axis xyz="0 0 1"/>
    <limit lower="0.0" upper="1.57" effort="5" velocity="1.0"/>
</joint>

    <!-- Garras -->
    <link name="finger_left_1">
        <visual>
            <geometry>
                <box size="0.02 0.12 0.05"/>
            </geometry>
            <material name="black"/>
        </visual>
		<inertial>
    		<mass value="0.2"/>
    		<origin xyz="0 0 0"/>
    		<inertia ixx="0.005" ixy="0.0" ixz="0.0" iyy="0.005" iyz="0.0" izz="0.001"/>
		</inertial>
    </link>
    <joint name="joint_finger_left_1" type="revolute">
        <parent link="gripper_base_left"/>
        <child link="finger_left_1"/>
        <origin xyz="0.05 0 -0.05" rpy="0 0 0"/>
        <axis xyz="0 1 0"/>
		<limit lower="-0.45" upper="0.45" effort="10" velocity="1.0"/>
    </joint>

    <link name="finger_right_1">
        <visual>
            <geometry>
                <box size="0.02 0.12 0.05"/>
            </geometry>
            <material name="black"/>
        </visual>
    </link>
    <joint name="joint_finger_right_1" type="revolute">
        <parent link="gripper_base_left"/>
        <child link="finger_right_1"/>
        <origin xyz="-0.05 0 -0.05" rpy="0 0 0"/>
        <axis xyz="0 1 0"/>
		<limit lower="-0.45" upper="0.45" effort="10" velocity="1.0"/>
    	<mimic joint="joint_finger_left_2" multiplier="-1.0" offset="0"/>
	</joint>

    <link name="finger_left_2">
        <visual>
            <geometry>
                <box size="0.02 0.12 0.05"/>
            </geometry>
            <material name="black"/>
        </visual>
    </link>
    <joint name="joint_finger_left_2" type="revolute">
        <parent link="gripper_base_right"/>
        <child link="finger_left_2"/>
        <origin xyz="0.05 0 -0.05" rpy="0 0 0"/>
        <axis xyz="0 1 0"/>
		<limit lower="-0.45" upper="0.45" effort="10" velocity="1.0"/>
    </joint>

    <link name="finger_right_2">
        <visual>
            <geometry>
                <box size="0.02 0.12 0.05"/>
            </geometry>
            <material name="black"/>
        </visual>
    </link>
    <joint name="joint_finger_right_2" type="revolute">
        <parent link="gripper_base_right"/>
        <child link="finger_right_2"/>
        <origin xyz="-0.05 0 -0.05" rpy="0 0 0"/>
        <axis xyz="0 1 0"/>
		<limit lower="-0.45" upper="0.45" effort="10" velocity="1.0"/>
		<mimic joint="joint_finger_left_2" multiplier="-1.0" offset="0"/>
    </joint>

</robot>
